Workbook
Name Z_BE54E0AD_3725_4423_92D7_4F1C045BE1BC_.wvu.Cols: methodName1!$E:$E
Name Z_6F1DCD5D_5DAC_4817_BF40_2B66F6F593E6_.wvu.Cols: methodName1!$E:$E
Name Z_6F1DCD5D_5DAC_4817_BF40_2B66F6F593E6_.wvu.PrintArea: Statistics!$A:$I
Name Z_2C0D9096_8D85_462A_A9B5_0B488ADB4269_.wvu.Cols: methodName1!$E:$E
Name ACTION: #REF!
Name Z_BE54E0AD_3725_4423_92D7_4F1C045BE1BC_.wvu.Cols: methodName2!$E:$E
Name Z_2C0D9096_8D85_462A_A9B5_0B488ADB4269_.wvu.PrintArea: Statistics!$A:$I
Name Z_2C0D9096_8D85_462A_A9B5_0B488ADB4269_.wvu.Cols: methodName2!$E:$E
Name Z_BE54E0AD_3725_4423_92D7_4F1C045BE1BC_.wvu.PrintArea: Statistics!$A:$I
Name Z_6F1DCD5D_5DAC_4817_BF40_2B66F6F593E6_.wvu.Cols: methodName2!$E:$E

Sheet Guideline
A1: Guideline to make and understand Unit Test Case
A3: 1. Overview
A4: - In the template, Unit test cases are based on functions. Each sheet presents test cases for one function.
A5: - Cover: General information of the project and Unit Test cases
A6: - FunctionList: The list of Classes and Functions in the document. + To control that the number of Unit TC meets customer's requirement or the norm, user should fill value for 'Normal number of Test cases/KLOC'.
A7: + Click on Function link to open the related Test cases of the function. Note: You should create new Function sheet before creating the link
A8: - Test Report: provive the overview results of Functions Unit test: Test coverage, Test successful coverage (Summary, for normal/abnormal/boundary cases)
A9: Note: Should check the formula of "Sub Total" if you add more functions
A11: 2. Content in Test function sheet
A12: 2.1 Combination of test cases.
A13: - To verify that number of Unit TC meets customer's requirement or not. User has to fill number LOC of tested function and fill value of 'Normal number test cases/KLOC' item in FunctionList sheet, which is required by customer or normal value. The number of lacked TC is shown in 'Lack of test cases' item.
A14: - If the number of Unit TC does not meet the requirement, creator should explain the reasons.
... A46: - Test requirement: Brief description about requirements which are tested in this function, it is not mandatory.

Sheet Cover
B2: UNIT TEST DOCUMENT
A4: Project Name | B4: <Project Name> | E4: Creator
A5: Project Code | B5: <Project Code> | E5: Issue Date | F5: <Date when this test report is created>
A6: Document Code | B6: =B5&"_"&"XXX"&"_"&"vx.x" -> <Project Code>_XXX_vx.x | E6: Version
A9: Record of change
A10: Effective Date | B10: Version | C10: Change Item | D10: *A,D,M | E10: Change description | F10: Reference
A11: <Date when these changes are effective> | F11: <List of documents which are refered in this version.>

Sheet MethodList
C2: Method List
A4: Project Name | C4: =Cover!B4 -> <Project Name>
A5: Project Code | C5: =Cover!B5 -> <Project Code>
A6: Test Environment Setup Description | C6: <List enviroment requires in this system 1. Server 2. Database 3. Web Browser ... >
A8: No | B8: Module Name | C8: Method Name | D8: Sheet Name | E8: Description | F8: Pre-Condition
A9: 1 | B9: ModuleName1 | C9: methodName1 | D9: methodName1
A10: 2 | B10: ModuleName2 | C10: methodName2 | D10: methodName2

Sheet Statistics
A2: UNIT TEST REPORT
A4: Project Name | B4: =Cover!B4 -> <Project Name> | D4: Creator
A5: Project Code | B5: =Cover!B5 -> <Project Code> | D5: Reviewer/Approver
A6: Document Code | B6: =B5&"_"&"Test Report"&"_"&"vx.x" -> <Project Code>_Test Report_vx.x | D6: Issue Date | F6: <Date when this test report is created>
A7: Notes | B7: <List modules included in this release> ex: Release 1 includes 2 modules: Module1 and Module2
A11: No | B11: Function code | C11: Passed | D11: Failed | E11: Untested | F11: N | G11: A | H11: B | I11: Total Test Cases
A12: 1 | B12: methodName1 | C12: =methodName1!A5 -> 0 | D12: =methodName1!C5 -> 0 | E12: =methodName1!F5 -> 15 | F12: =methodName1!L5 -> 0 | G12: =methodName1!M5 -> 0 | H12: =methodName1!N5 -> 0 | I12: =methodName1!O5 -> 15
A13: 2 | B13: methodName2 | C13: =methodName2!A5 -> 12 | D13: =methodName2!C5 -> 3 | E13: =methodName2!F5 -> 0 | F13: =methodName2!L5 -> 12 | G13: =methodName2!M5 -> 2 | H13: =methodName2!N5 -> 1 | I13: =methodName2!O5 -> 15
B16: Sub total | C16: =SUM(C10:C15) -> 12 | D16: =SUM(D10:D15) -> 3 | E16: =SUM(E10:E15) -> 15 | F16: =SUM(F10:F15) -> 12 | G16: =SUM(G10:G15) -> 2 | H16: =SUM(H10:H15) -> 1 | I16: =SUM(I10:I15) -> 30
B18: Test coverage | D18: =(C16+D16)*100/(I16) -> 50 | E18: %
B19: Test successful coverage | D19: =C16*100/(I16) -> 40 | E19: %
B20: Normal case | D20: =F16*100/I16 -> 40 | E20: %
B21: Abnormal case | D21: =G16*100/I16 -> 6.6666667 | E21: %
B22: Boundary case | D22: =H16*100/I16 -> 3.3333333 | E22: %

Sheet methodName1
A1: Code Module | C1: ModuleName1 | F1: Method | L1: methodName1
A2: Created By | C2: <Developer Name> | F2: Executed By
A3: Test requirement | C3: <Brief description about requirements which are tested in this function>
A4: Passed | C4: Failed | F4: Untested | L4: N/A/B | O4: Total Test Cases
A5: =COUNTIF(F58:HQ58,"P") -> 0 | C5: =COUNTIF(F58:HQ58,"F") -> 0 | F5: =SUM(O5,-A5,-C5) -> 15 | L5: =COUNTIF(E57:HQ57,"N") -> 0 | M5: =COUNTIF(E57:HQ57,"A") -> 0 | N5: =COUNTIF(E57:HQ57,"B") -> 0 | O5: =COUNTA(E7:HT7) -> 15
F7: UTCID01 | G7: UTCID02 | H7: UTCID03 | I7: UTCID04 | J7: UTCID05 | K7: UTCID06 | L7: UTCID07 | M7: UTCID08 | N7: UTCID09 | O7: UTCID10 | P7: UTCID11 | Q7: UTCID12 | R7: UTCID13 | S7: UTCID14 | T7: UTCID15
A8: Condition | B8: Precondition
D9: Can connect with server | E9: O | F9: O
B11: (type)
D12: valid object | E12: O | F12: O | G12: O | H12: O | K12: O | L12: O | M12: O | N12: O | O12: O | P12: O | Q12: O | R12: O | S12: O | T12: O
D13: null
D14: "string" (not an object) | H14: O
B15: p.name | I15: O
D16: "Profile A" (normal) | J16: O
D17: "A" (1 character) | K17: O
D18: "A"×120 (120 characters)
D19: ""
D20: "A"×121 (121 characters)
D21: "p"
B22: p.startUrl
D23: (not provided) | E23: O | F23: O
D24: "unknown" (invalid value) | G24: O
B25: p.fingerprint.browser | H25: O
D26: (not provided) | I26: O
D27: "Safari" (unsupported value) | J27: O
B28: p.settings.engine | K28: O
D29: (not provided)
D30: "unknown" (invalid value)
B31: p.settings.cpuCores
D32: (not provided)
D33: 0 (below min)
D34: 65 (above max)
D35: 1 (min boundary)
D36: 64 (max boundary)
B37: p.settings.memoryGB
D38: (not provided)
D39: 257 (above max)
A40: Confirm | B40: Return
D41: [] (no errors) | F41: O | G41: O | H41: O | I41: O
D42: ['Payload must be object']
...

Sheet Sheet1

Sheet methodName2
A1: Code Module | C1: ModuleName2 | F1: Method | L1: methodName2
A2: Created By | C2: <Developer Name> | F2: Executed By
A3: Test requirement | C3: <Brief description about requirements which are tested in this function>
A4: Passed | C4: Failed | F4: Untested | L4: N/A/B | O4: Total Test Cases
A5: =COUNTIF(F38:HQ38,"P") -> 12 | C5: =COUNTIF(F38:HQ38,"F") -> 3 | F5: =SUM(O5,-A5,-C5) -> 0 | L5: =COUNTIF(E37:HQ37,"N") -> 12 | M5: =COUNTIF(E37:HQ37,"A") -> 2 | N5: =COUNTIF(E37:HQ37,"B") -> 1 | O5: =COUNTA(E7:HT7) -> 15
F7: UTCID01 | G7: UTCID02 | H7: UTCID03 | I7: UTCID04 | J7: UTCID05 | K7: UTCID06 | L7: UTCID07 | M7: UTCID08 | N7: UTCID09 | O7: UTCID10 | P7: UTCID11 | Q7: UTCID12 | R7: UTCID13 | S7: UTCID14 | T7: UTCID15
A8: Condition | B8: Precondition
D9: Can connect with server
B12: Input1
D13: "1"
D14: ""
D15: null
B16: Input2
D17: >=5 & <= 10
D18: 5
D19: 10
A29: Confirm | B29: Return
D30: 1
D31: 2
B32: Exception
B34: Log message
D35: "success"
D36: "input1 is null"
A37: Result | B37: Type(N : Normal, A : Abnormal, B : Boundary) | F37: N | G37: N | H37: N | I37: N | J37: N | K37: B | L37: A | M37: N | N37: N | O37: N | P37: N | Q37: N | R37: A | S37: N | T37: N
B38: Passed/Failed | F38: P | G38: P | H38: P | I38: P | J38: P | K38: F | L38: F | M38: P | N38: P | O38: P | P38: P | Q38: P | R38: F | S38: P | T38: P
B39: Executed Date | F39: 39139 | G39: 39139 | H39: 39140 | I39: 39141 | J39: 39142 | K39: 39143 | L39: 39144 | M39: 39145 | N39: 39146 | O39: 39147 | P39: 39148 | Q39: 39149 | R39: 39150 | S39: 39151 | T39: 39152
B40: Defect ID | K40: DFID002 | L40: DFID004 | M40: DFID005 | N40: DFID006 | O40: DFID007 | P40: DFID008 | Q40: DFID009 | R40: DFID010 | S40: DFID011 | T40: DFID012

Sheet Example
A1: Code Module | C1: ModuleName | F1: Method | L1: methodName
A2: Created By | C2: <Developer Name> | F2: Executed By
A3: Test requirement | C3: <Brief description about requirements which are tested in this function>
A4: Passed | C4: Failed | F4: Untested | L4: N/A/B | O4: Total Test Cases
A5: =COUNTIF(F45:HQ45,"P") -> 0 | C5: =COUNTIF(F45:HQ45,"F") -> 0 | F5: =SUM(O5,-A5,-C5) -> 15 | L5: =COUNTIF(E44:HQ44,"N") -> 0 | M5: =COUNTIF(E44:HQ44,"A") -> 0 | N5: =COUNTIF(E44:HQ44,"B") -> 0 | O5: =COUNTA(E7:HT7) -> 15
F7: UTCID01 | G7: UTCID02 | H7: UTCID02 | I7: UTCID02 | J7: UTCID02 | K7: UTCID02 | L7: UTCID07 | M7: UTCID08 | N7: UTCID09 | O7: UTCID10 | P7: UTCID11 | Q7: UTCID12 | R7: UTCID13 | S7: UTCID14 | T7: UTCID15
A8: Condition | B8: Precondition
B12: a
D13: -2 | F13: O
D14: -1 | L14: O
D15: 0 | G15: O | H15: O | I15: O
D16: 1 | J16: O | K16: O
B17: b
D18: 0 | G18: O | H18: O
D19: -2 | J19: O | K19: O | L19: O
D20: 2 | I20: O
B21: c
D22: 0 | G22: O
D23: 1 | H23: O | I23: O | J23: O
D24: 3 | L24: O
D25: 5 | K25: O
A31: Confirm | B31: Return
B32: list
D33: null | F33: O | H33: O | K33: O
D34: size = 0 | G34: O
D35: {-1/2} | I35: O
D36: {1,1} | J36: O
D37: {1,-3} | L37: O
B38: Exception
B40: Log message
D41: "please input a>= -1" | F41: O
A43: Result | B43: Type(N : Normal, A : Abnormal, B : Boundary) | F43: A | G43: N | H43: N | I43: N | J43: N | K43: N | L43: B
B44: Passed/Failed
B45: Executed Date | F45: 39139 | G45: 39139 | H45: 39139 | I45: 39139 | J45: 39139 | K45: 39139 | L45: 39144
B46: Defect ID
